============================= test session starts ==============================
platform linux -- Python 3.10.12, pytest-7.4.0, pluggy-1.2.0
rootdir: /home/jake/Development/exercism-python
configfile: pytest.ini
plugins: mock-3.11.1, reportlog-0.4.0, repeat-0.9.1, asyncio-0.21.1
asyncio: mode=strict
collected 11 items

exercises/practice/series/series_test.py F.FFF......                     [100%]

=================================== FAILURES ===================================
___________________ SeriesTest.test_empty_series_is_invalid ____________________

self = <series_test.SeriesTest testMethod=test_empty_series_is_invalid>

    def test_empty_series_is_invalid(self):
>       with self.assertRaises(ValueError) as err:
E       AssertionError: ValueError not raised

exercises/practice/series/series_test.py:63: AssertionError
_________________ SeriesTest.test_slice_length_cannot_be_zero __________________

self = <series_test.SeriesTest testMethod=test_slice_length_cannot_be_zero>

    def test_slice_length_cannot_be_zero(self):
        with self.assertRaises(ValueError) as err:
            slices("12345", 0)
        self.assertEqual(type(err.exception), ValueError)
>       self.assertEqual(err.exception.args[0], "slice length cannot be zero")
E       AssertionError: 'slice length cannot be negative' != 'slice length cannot be zero'
E       - slice length cannot be negative
E       ?                        ^ ^^^^^^
E       + slice length cannot be zero
E       ?                        ^ ^^

exercises/practice/series/series_test.py:54: AssertionError
__________________ SeriesTest.test_slice_length_is_too_large ___________________

self = <series_test.SeriesTest testMethod=test_slice_length_is_too_large>

    def test_slice_length_is_too_large(self):
>       with self.assertRaises(ValueError) as err:
E       AssertionError: ValueError not raised

exercises/practice/series/series_test.py:35: AssertionError
________________ SeriesTest.test_slice_length_is_way_too_large _________________

self = <series_test.SeriesTest testMethod=test_slice_length_is_way_too_large>

    def test_slice_length_is_way_too_large(self):
>       with self.assertRaises(ValueError) as err:
E       AssertionError: ValueError not raised

exercises/practice/series/series_test.py:43: AssertionError
=========================== short test summary info ============================
FAILED exercises/practice/series/series_test.py::SeriesTest::test_empty_series_is_invalid
FAILED exercises/practice/series/series_test.py::SeriesTest::test_slice_length_cannot_be_zero
FAILED exercises/practice/series/series_test.py::SeriesTest::test_slice_length_is_too_large
FAILED exercises/practice/series/series_test.py::SeriesTest::test_slice_length_is_way_too_large
========================= 4 failed, 7 passed in 0.04s ==========================
