============================= test session starts ==============================
platform linux -- Python 3.10.12, pytest-7.4.0, pluggy-1.2.0
rootdir: /home/jake/Development/exercism-python
configfile: pytest.ini
plugins: mock-3.11.1, reportlog-0.4.0, repeat-0.9.1
collected 16 items

exercises/practice/sum-of-multiples/sum_of_multiples_test.py FFFFFFFFFFF [ 68%]
FFFFF                                                                    [100%]

=================================== FAILURES ===================================
_________________ SumOfMultiplesTest.test_a_much_larger_limit __________________

self = <sum_of_multiples_test.SumOfMultiplesTest testMethod=test_a_much_larger_limit>

    def test_a_much_larger_limit(self):
>       self.assertEqual(sum_of_multiples(1000, [3, 5]), 233168)
E       AssertionError: None != 233168

exercises/practice/sum-of-multiples/sum_of_multiples_test.py:29: AssertionError
____________ SumOfMultiplesTest.test_all_numbers_are_multiples_of_1 ____________

self = <sum_of_multiples_test.SumOfMultiplesTest testMethod=test_all_numbers_are_multiples_of_1>

    def test_all_numbers_are_multiples_of_1(self):
>       self.assertEqual(sum_of_multiples(100, [1]), 4950)
E       AssertionError: None != 4950

exercises/practice/sum-of-multiples/sum_of_multiples_test.py:47: AssertionError
__________ SumOfMultiplesTest.test_each_multiple_is_only_counted_once __________

self = <sum_of_multiples_test.SumOfMultiplesTest testMethod=test_each_multiple_is_only_counted_once>

    def test_each_multiple_is_only_counted_once(self):
>       self.assertEqual(sum_of_multiples(100, [3, 5]), 2318)
E       AssertionError: None != 2318

exercises/practice/sum-of-multiples/sum_of_multiples_test.py:26: AssertionError
_____________ SumOfMultiplesTest.test_factors_not_relatively_prime _____________

self = <sum_of_multiples_test.SumOfMultiplesTest testMethod=test_factors_not_relatively_prime>

    def test_factors_not_relatively_prime(self):
>       self.assertEqual(sum_of_multiples(15, [4, 6]), 30)
E       AssertionError: None != 30

exercises/practice/sum-of-multiples/sum_of_multiples_test.py:35: AssertionError
___ SumOfMultiplesTest.test_more_than_one_factor_with_multiples_within_limit ___

self = <sum_of_multiples_test.SumOfMultiplesTest testMethod=test_more_than_one_factor_with_multiples_within_limit>

    def test_more_than_one_factor_with_multiples_within_limit(self):
>       self.assertEqual(sum_of_multiples(10, [3, 5]), 23)
E       AssertionError: None != 23

exercises/practice/sum-of-multiples/sum_of_multiples_test.py:23: AssertionError
_________ SumOfMultiplesTest.test_more_than_one_multiple_within_limit __________

self = <sum_of_multiples_test.SumOfMultiplesTest testMethod=test_more_than_one_multiple_within_limit>

    def test_more_than_one_multiple_within_limit(self):
>       self.assertEqual(sum_of_multiples(7, [3]), 9)
E       AssertionError: None != 9

exercises/practice/sum-of-multiples/sum_of_multiples_test.py:20: AssertionError
_________________ SumOfMultiplesTest.test_much_larger_factors __________________

self = <sum_of_multiples_test.SumOfMultiplesTest testMethod=test_much_larger_factors>

    def test_much_larger_factors(self):
>       self.assertEqual(sum_of_multiples(10000, [43, 47]), 2203160)
E       AssertionError: None != 2203160

exercises/practice/sum-of-multiples/sum_of_multiples_test.py:44: AssertionError
____________ SumOfMultiplesTest.test_no_factors_means_an_empty_sum _____________

self = <sum_of_multiples_test.SumOfMultiplesTest testMethod=test_no_factors_means_an_empty_sum>

    def test_no_factors_means_an_empty_sum(self):
>       self.assertEqual(sum_of_multiples(10000, []), 0)
E       AssertionError: None != 0

exercises/practice/sum-of-multiples/sum_of_multiples_test.py:50: AssertionError
______________ SumOfMultiplesTest.test_no_multiples_within_limit _______________

self = <sum_of_multiples_test.SumOfMultiplesTest testMethod=test_no_multiples_within_limit>

    def test_no_multiples_within_limit(self):
>       self.assertEqual(sum_of_multiples(1, [3, 5]), 0)
E       AssertionError: None != 0

exercises/practice/sum-of-multiples/sum_of_multiples_test.py:14: AssertionError
________ SumOfMultiplesTest.test_one_factor_has_multiples_within_limit _________

self = <sum_of_multiples_test.SumOfMultiplesTest testMethod=test_one_factor_has_multiples_within_limit>

    def test_one_factor_has_multiples_within_limit(self):
>       self.assertEqual(sum_of_multiples(4, [3, 5]), 3)
E       AssertionError: None != 3

exercises/practice/sum-of-multiples/sum_of_multiples_test.py:17: AssertionError
_________ SumOfMultiplesTest.test_one_factor_is_a_multiple_of_another __________

self = <sum_of_multiples_test.SumOfMultiplesTest testMethod=test_one_factor_is_a_multiple_of_another>

    def test_one_factor_is_a_multiple_of_another(self):
>       self.assertEqual(sum_of_multiples(51, [5, 25]), 275)
E       AssertionError: None != 275

exercises/practice/sum-of-multiples/sum_of_multiples_test.py:41: AssertionError
_ SumOfMultiplesTest.test_solutions_using_include_exclude_must_extend_to_cardinality_greater_than_3 _

self = <sum_of_multiples_test.SumOfMultiplesTest testMethod=test_solutions_using_include_exclude_must_extend_to_cardinality_greater_than_3>

    def test_solutions_using_include_exclude_must_extend_to_cardinality_greater_than_3(
        self,
    ):
>       self.assertEqual(sum_of_multiples(10000, [2, 3, 5, 7, 11]), 39614537)
E       AssertionError: None != 39614537

exercises/practice/sum-of-multiples/sum_of_multiples_test.py:61: AssertionError
_ SumOfMultiplesTest.test_some_pairs_of_factors_relatively_prime_and_some_not __

self = <sum_of_multiples_test.SumOfMultiplesTest testMethod=test_some_pairs_of_factors_relatively_prime_and_some_not>

    def test_some_pairs_of_factors_relatively_prime_and_some_not(self):
>       self.assertEqual(sum_of_multiples(150, [5, 6, 8]), 4419)
E       AssertionError: None != 4419

exercises/practice/sum-of-multiples/sum_of_multiples_test.py:38: AssertionError
_ SumOfMultiplesTest.test_the_factor_0_does_not_affect_the_sum_of_multiples_of_other_factors _

self = <sum_of_multiples_test.SumOfMultiplesTest testMethod=test_the_factor_0_does_not_affect_the_sum_of_multiples_of_other_factors>

    def test_the_factor_0_does_not_affect_the_sum_of_multiples_of_other_factors(self):
>       self.assertEqual(sum_of_multiples(4, [3, 0]), 3)
E       AssertionError: None != 3

exercises/practice/sum-of-multiples/sum_of_multiples_test.py:56: AssertionError
_____________ SumOfMultiplesTest.test_the_only_multiple_of_0_is_0 ______________

self = <sum_of_multiples_test.SumOfMultiplesTest testMethod=test_the_only_multiple_of_0_is_0>

    def test_the_only_multiple_of_0_is_0(self):
>       self.assertEqual(sum_of_multiples(1, [0]), 0)
E       AssertionError: None != 0

exercises/practice/sum-of-multiples/sum_of_multiples_test.py:53: AssertionError
____________________ SumOfMultiplesTest.test_three_factors _____________________

self = <sum_of_multiples_test.SumOfMultiplesTest testMethod=test_three_factors>

    def test_three_factors(self):
>       self.assertEqual(sum_of_multiples(20, [7, 13, 17]), 51)
E       AssertionError: None != 51

exercises/practice/sum-of-multiples/sum_of_multiples_test.py:32: AssertionError
=========================== short test summary info ============================
FAILED exercises/practice/sum-of-multiples/sum_of_multiples_test.py::SumOfMultiplesTest::test_a_much_larger_limit
FAILED exercises/practice/sum-of-multiples/sum_of_multiples_test.py::SumOfMultiplesTest::test_all_numbers_are_multiples_of_1
FAILED exercises/practice/sum-of-multiples/sum_of_multiples_test.py::SumOfMultiplesTest::test_each_multiple_is_only_counted_once
FAILED exercises/practice/sum-of-multiples/sum_of_multiples_test.py::SumOfMultiplesTest::test_factors_not_relatively_prime
FAILED exercises/practice/sum-of-multiples/sum_of_multiples_test.py::SumOfMultiplesTest::test_more_than_one_factor_with_multiples_within_limit
FAILED exercises/practice/sum-of-multiples/sum_of_multiples_test.py::SumOfMultiplesTest::test_more_than_one_multiple_within_limit
FAILED exercises/practice/sum-of-multiples/sum_of_multiples_test.py::SumOfMultiplesTest::test_much_larger_factors
FAILED exercises/practice/sum-of-multiples/sum_of_multiples_test.py::SumOfMultiplesTest::test_no_factors_means_an_empty_sum
FAILED exercises/practice/sum-of-multiples/sum_of_multiples_test.py::SumOfMultiplesTest::test_no_multiples_within_limit
FAILED exercises/practice/sum-of-multiples/sum_of_multiples_test.py::SumOfMultiplesTest::test_one_factor_has_multiples_within_limit
FAILED exercises/practice/sum-of-multiples/sum_of_multiples_test.py::SumOfMultiplesTest::test_one_factor_is_a_multiple_of_another
FAILED exercises/practice/sum-of-multiples/sum_of_multiples_test.py::SumOfMultiplesTest::test_solutions_using_include_exclude_must_extend_to_cardinality_greater_than_3
FAILED exercises/practice/sum-of-multiples/sum_of_multiples_test.py::SumOfMultiplesTest::test_some_pairs_of_factors_relatively_prime_and_some_not
FAILED exercises/practice/sum-of-multiples/sum_of_multiples_test.py::SumOfMultiplesTest::test_the_factor_0_does_not_affect_the_sum_of_multiples_of_other_factors
FAILED exercises/practice/sum-of-multiples/sum_of_multiples_test.py::SumOfMultiplesTest::test_the_only_multiple_of_0_is_0
FAILED exercises/practice/sum-of-multiples/sum_of_multiples_test.py::SumOfMultiplesTest::test_three_factors
============================== 16 failed in 0.07s ==============================
