============================= test session starts ==============================
platform linux -- Python 3.10.12, pytest-7.4.0, pluggy-1.3.0
rootdir: /home/jake/Development/mentat/tests/benchmarks/repos/exercism-python
configfile: pytest.ini
plugins: mock-3.11.1, reportlog-0.4.0, asyncio-0.21.1, xdist-3.3.1
asyncio: mode=strict
collected 23 items

exercises/practice/luhn/luhn_test.py FF.FFFFFFFF.....FFF...F             [100%]

=================================== FAILURES ===================================
______ LuhnTest.test_a_simple_valid_sin_that_becomes_invalid_if_reversed _______

self = <luhn_test.LuhnTest testMethod=test_a_simple_valid_sin_that_becomes_invalid_if_reversed>

    def test_a_simple_valid_sin_that_becomes_invalid_if_reversed(self):
>       self.assertIs(Luhn("59").valid(), True)
E       AssertionError: None is not True

exercises/practice/luhn/luhn_test.py:23: AssertionError
_______ LuhnTest.test_a_simple_valid_sin_that_remains_valid_if_reversed ________

self = <luhn_test.LuhnTest testMethod=test_a_simple_valid_sin_that_remains_valid_if_reversed>

    def test_a_simple_valid_sin_that_remains_valid_if_reversed(self):
>       self.assertIs(Luhn("059").valid(), True)
E       AssertionError: None is not True

exercises/practice/luhn/luhn_test.py:20: AssertionError
______________________ LuhnTest.test_a_valid_canadian_sin ______________________

self = <luhn_test.LuhnTest testMethod=test_a_valid_canadian_sin>

    def test_a_valid_canadian_sin(self):
>       self.assertIs(Luhn("055 444 285").valid(), True)
E       AssertionError: None is not True

exercises/practice/luhn/luhn_test.py:26: AssertionError
_____ LuhnTest.test_input_digit_9_is_correctly_converted_to_output_digit_9 _____

self = <luhn_test.LuhnTest testMethod=test_input_digit_9_is_correctly_converted_to_output_digit_9>

    def test_input_digit_9_is_correctly_converted_to_output_digit_9(self):
>       self.assertIs(Luhn("091").valid(), True)
E       AssertionError: None is not True

exercises/practice/luhn/luhn_test.py:62: AssertionError
______________________ LuhnTest.test_invalid_canadian_sin ______________________

self = <luhn_test.LuhnTest testMethod=test_invalid_canadian_sin>

    def test_invalid_canadian_sin(self):
>       self.assertIs(Luhn("055 444 286").valid(), False)
E       AssertionError: None is not False

exercises/practice/luhn/luhn_test.py:29: AssertionError
______________________ LuhnTest.test_invalid_credit_card _______________________

self = <luhn_test.LuhnTest testMethod=test_invalid_credit_card>

    def test_invalid_credit_card(self):
>       self.assertIs(Luhn("8273 1232 7352 0569").valid(), False)
E       AssertionError: None is not False

exercises/practice/luhn/luhn_test.py:32: AssertionError
______ LuhnTest.test_invalid_long_number_with_a_remainder_divisible_by_5 _______

self = <luhn_test.LuhnTest testMethod=test_invalid_long_number_with_a_remainder_divisible_by_5>

    def test_invalid_long_number_with_a_remainder_divisible_by_5(self):
>       self.assertIs(Luhn("1 2345 6789 1234 5678 9013").valid(), False)
E       AssertionError: None is not False

exercises/practice/luhn/luhn_test.py:38: AssertionError
___________ LuhnTest.test_invalid_long_number_with_an_even_remainder ___________

self = <luhn_test.LuhnTest testMethod=test_invalid_long_number_with_an_even_remainder>

    def test_invalid_long_number_with_an_even_remainder(self):
>       self.assertIs(Luhn("1 2345 6789 1234 5678 9012").valid(), False)
E       AssertionError: None is not False

exercises/practice/luhn/luhn_test.py:35: AssertionError
_______________ LuhnTest.test_is_valid_can_be_called_repeatedly ________________

self = <luhn_test.LuhnTest testMethod=test_is_valid_can_be_called_repeatedly>

    def test_is_valid_can_be_called_repeatedly(self):
        # This test was added, because we saw many implementations
        # in which the first call to valid() worked, but the
        # second call failed().
        number = Luhn("055 444 285")
>       self.assertIs(number.valid(), True)
E       AssertionError: None is not True

exercises/practice/luhn/luhn_test.py:88: AssertionError
________________ LuhnTest.test_more_than_a_single_zero_is_valid ________________

self = <luhn_test.LuhnTest testMethod=test_more_than_a_single_zero_is_valid>

    def test_more_than_a_single_zero_is_valid(self):
>       self.assertIs(Luhn("0000 0").valid(), True)
E       AssertionError: None is not True

exercises/practice/luhn/luhn_test.py:59: AssertionError
_ LuhnTest.test_valid_luhn_with_an_odd_number_of_digits_and_non_zero_first_digit _

self = <luhn_test.LuhnTest testMethod=test_valid_luhn_with_an_odd_number_of_digits_and_non_zero_first_digit>

    def test_valid_luhn_with_an_odd_number_of_digits_and_non_zero_first_digit(self):
>       self.assertIs(Luhn("109").valid(), True)
E       AssertionError: None is not True

exercises/practice/luhn/luhn_test.py:68: AssertionError
___________ LuhnTest.test_valid_number_with_an_even_number_of_digits ___________

self = <luhn_test.LuhnTest testMethod=test_valid_number_with_an_even_number_of_digits>

    def test_valid_number_with_an_even_number_of_digits(self):
>       self.assertIs(Luhn("095 245 88").valid(), True)
E       AssertionError: None is not True

exercises/practice/luhn/luhn_test.py:41: AssertionError
___________ LuhnTest.test_valid_number_with_an_odd_number_of_spaces ____________

self = <luhn_test.LuhnTest testMethod=test_valid_number_with_an_odd_number_of_spaces>

    def test_valid_number_with_an_odd_number_of_spaces(self):
>       self.assertIs(Luhn("234 567 891 234").valid(), True)
E       AssertionError: None is not True

exercises/practice/luhn/luhn_test.py:44: AssertionError
____________________ LuhnTest.test_very_long_input_is_valid ____________________

self = <luhn_test.LuhnTest testMethod=test_very_long_input_is_valid>

    def test_very_long_input_is_valid(self):
>       self.assertIs(Luhn("9999999999 9999999999 9999999999 9999999999").valid(), True)
E       AssertionError: None is not True

exercises/practice/luhn/luhn_test.py:65: AssertionError
=========================== short test summary info ============================
FAILED exercises/practice/luhn/luhn_test.py::LuhnTest::test_a_simple_valid_sin_that_becomes_invalid_if_reversed
FAILED exercises/practice/luhn/luhn_test.py::LuhnTest::test_a_simple_valid_sin_that_remains_valid_if_reversed
FAILED exercises/practice/luhn/luhn_test.py::LuhnTest::test_a_valid_canadian_sin
FAILED exercises/practice/luhn/luhn_test.py::LuhnTest::test_input_digit_9_is_correctly_converted_to_output_digit_9
FAILED exercises/practice/luhn/luhn_test.py::LuhnTest::test_invalid_canadian_sin
FAILED exercises/practice/luhn/luhn_test.py::LuhnTest::test_invalid_credit_card
FAILED exercises/practice/luhn/luhn_test.py::LuhnTest::test_invalid_long_number_with_a_remainder_divisible_by_5
FAILED exercises/practice/luhn/luhn_test.py::LuhnTest::test_invalid_long_number_with_an_even_remainder
FAILED exercises/practice/luhn/luhn_test.py::LuhnTest::test_is_valid_can_be_called_repeatedly
FAILED exercises/practice/luhn/luhn_test.py::LuhnTest::test_more_than_a_single_zero_is_valid
FAILED exercises/practice/luhn/luhn_test.py::LuhnTest::test_valid_luhn_with_an_odd_number_of_digits_and_non_zero_first_digit
FAILED exercises/practice/luhn/luhn_test.py::LuhnTest::test_valid_number_with_an_even_number_of_digits
FAILED exercises/practice/luhn/luhn_test.py::LuhnTest::test_valid_number_with_an_odd_number_of_spaces
FAILED exercises/practice/luhn/luhn_test.py::LuhnTest::test_very_long_input_is_valid
========================= 14 failed, 9 passed in 0.12s =========================
